2020-12-20 19:25:54,758 ERROR: Exception on /unfollow/john [POST] [in /home/akshay/Documents/flask-projects/microblog/micro-venv/lib/python3.6/site-packages/flask/app.py:1892]
Traceback (most recent call last):
  File "/home/akshay/Documents/flask-projects/microblog/micro-venv/lib/python3.6/site-packages/flask/app.py", line 2447, in wsgi_app
    response = self.full_dispatch_request()
  File "/home/akshay/Documents/flask-projects/microblog/micro-venv/lib/python3.6/site-packages/flask/app.py", line 1952, in full_dispatch_request
    rv = self.handle_user_exception(e)
  File "/home/akshay/Documents/flask-projects/microblog/micro-venv/lib/python3.6/site-packages/flask/app.py", line 1821, in handle_user_exception
    reraise(exc_type, exc_value, tb)
  File "/home/akshay/Documents/flask-projects/microblog/micro-venv/lib/python3.6/site-packages/flask/_compat.py", line 39, in reraise
    raise value
  File "/home/akshay/Documents/flask-projects/microblog/micro-venv/lib/python3.6/site-packages/flask/app.py", line 1950, in full_dispatch_request
    rv = self.dispatch_request()
  File "/home/akshay/Documents/flask-projects/microblog/micro-venv/lib/python3.6/site-packages/flask/app.py", line 1936, in dispatch_request
    return self.view_functions[rule.endpoint](**req.view_args)
  File "/home/akshay/Documents/flask-projects/microblog/micro-venv/lib/python3.6/site-packages/flask_login/utils.py", line 272, in decorated_view
    return func(*args, **kwargs)
TypeError: unfollow() got an unexpected keyword argument 'username'
2020-12-20 19:27:15,181 INFO: Microblog startup [in /home/akshay/Documents/flask-projects/microblog/micro-venv/app/__init__.py:46]
2020-12-20 19:51:02,974 INFO: Microblog startup [in /home/akshay/Documents/flask-projects/microblog/micro-venv/app/__init__.py:46]
