2020-12-19 19:07:06,317 ERROR: Exception on /explore [GET] [in /home/akshay/Documents/flask-projects/microblog/micro-venv/lib/python3.6/site-packages/flask/app.py:1892]
Traceback (most recent call last):
  File "/home/akshay/Documents/flask-projects/microblog/micro-venv/lib/python3.6/site-packages/flask/app.py", line 2447, in wsgi_app
    response = self.full_dispatch_request()
  File "/home/akshay/Documents/flask-projects/microblog/micro-venv/lib/python3.6/site-packages/flask/app.py", line 1952, in full_dispatch_request
    rv = self.handle_user_exception(e)
  File "/home/akshay/Documents/flask-projects/microblog/micro-venv/lib/python3.6/site-packages/flask/app.py", line 1821, in handle_user_exception
    reraise(exc_type, exc_value, tb)
  File "/home/akshay/Documents/flask-projects/microblog/micro-venv/lib/python3.6/site-packages/flask/_compat.py", line 39, in reraise
    raise value
  File "/home/akshay/Documents/flask-projects/microblog/micro-venv/lib/python3.6/site-packages/flask/app.py", line 1950, in full_dispatch_request
    rv = self.dispatch_request()
  File "/home/akshay/Documents/flask-projects/microblog/micro-venv/lib/python3.6/site-packages/flask/app.py", line 1936, in dispatch_request
    return self.view_functions[rule.endpoint](**req.view_args)
  File "/home/akshay/Documents/flask-projects/microblog/micro-venv/lib/python3.6/site-packages/flask_login/utils.py", line 272, in decorated_view
    return func(*args, **kwargs)
  File "/home/akshay/Documents/flask-projects/microblog/micro-venv/app/routes.py", line 138, in explore
    post = Post.query.order_by(Post.timestamp.desc()).all()
NameError: name 'Post' is not defined
2020-12-19 19:08:19,905 INFO: Microblog startup [in /home/akshay/Documents/flask-projects/microblog/micro-venv/app/__init__.py:38]
2020-12-19 19:12:10,288 INFO: Microblog startup [in /home/akshay/Documents/flask-projects/microblog/micro-venv/app/__init__.py:38]
2020-12-19 19:16:58,279 INFO: Microblog startup [in /home/akshay/Documents/flask-projects/microblog/micro-venv/app/__init__.py:38]
2020-12-19 19:19:56,521 INFO: Microblog startup [in /home/akshay/Documents/flask-projects/microblog/micro-venv/app/__init__.py:38]
2020-12-19 19:20:24,285 ERROR: Exception on /index [POST] [in /home/akshay/Documents/flask-projects/microblog/micro-venv/lib/python3.6/site-packages/flask/app.py:1892]
Traceback (most recent call last):
  File "/home/akshay/Documents/flask-projects/microblog/micro-venv/lib/python3.6/site-packages/flask/app.py", line 2447, in wsgi_app
    response = self.full_dispatch_request()
  File "/home/akshay/Documents/flask-projects/microblog/micro-venv/lib/python3.6/site-packages/flask/app.py", line 1952, in full_dispatch_request
    rv = self.handle_user_exception(e)
  File "/home/akshay/Documents/flask-projects/microblog/micro-venv/lib/python3.6/site-packages/flask/app.py", line 1821, in handle_user_exception
    reraise(exc_type, exc_value, tb)
  File "/home/akshay/Documents/flask-projects/microblog/micro-venv/lib/python3.6/site-packages/flask/_compat.py", line 39, in reraise
    raise value
  File "/home/akshay/Documents/flask-projects/microblog/micro-venv/lib/python3.6/site-packages/flask/app.py", line 1950, in full_dispatch_request
    rv = self.dispatch_request()
  File "/home/akshay/Documents/flask-projects/microblog/micro-venv/lib/python3.6/site-packages/flask/app.py", line 1936, in dispatch_request
    return self.view_functions[rule.endpoint](**req.view_args)
  File "/home/akshay/Documents/flask-projects/microblog/micro-venv/lib/python3.6/site-packages/flask_login/utils.py", line 272, in decorated_view
    return func(*args, **kwargs)
  File "/home/akshay/Documents/flask-projects/microblog/micro-venv/app/routes.py", line 16, in index
    post == Post(body = form.post.data, author=current_user)
NameError: name 'post' is not defined
2020-12-19 19:20:57,409 INFO: Microblog startup [in /home/akshay/Documents/flask-projects/microblog/micro-venv/app/__init__.py:38]
2020-12-19 19:32:59,811 INFO: Microblog startup [in /home/akshay/Documents/flask-projects/microblog/micro-venv/app/__init__.py:38]
2020-12-19 19:33:03,949 ERROR: Exception on /index [GET] [in /home/akshay/Documents/flask-projects/microblog/micro-venv/lib/python3.6/site-packages/flask/app.py:1892]
Traceback (most recent call last):
  File "/home/akshay/Documents/flask-projects/microblog/micro-venv/lib/python3.6/site-packages/flask/app.py", line 2447, in wsgi_app
    response = self.full_dispatch_request()
  File "/home/akshay/Documents/flask-projects/microblog/micro-venv/lib/python3.6/site-packages/flask/app.py", line 1952, in full_dispatch_request
    rv = self.handle_user_exception(e)
  File "/home/akshay/Documents/flask-projects/microblog/micro-venv/lib/python3.6/site-packages/flask/app.py", line 1821, in handle_user_exception
    reraise(exc_type, exc_value, tb)
  File "/home/akshay/Documents/flask-projects/microblog/micro-venv/lib/python3.6/site-packages/flask/_compat.py", line 39, in reraise
    raise value
  File "/home/akshay/Documents/flask-projects/microblog/micro-venv/lib/python3.6/site-packages/flask/app.py", line 1950, in full_dispatch_request
    rv = self.dispatch_request()
  File "/home/akshay/Documents/flask-projects/microblog/micro-venv/lib/python3.6/site-packages/flask/app.py", line 1936, in dispatch_request
    return self.view_functions[rule.endpoint](**req.view_args)
  File "/home/akshay/Documents/flask-projects/microblog/micro-venv/lib/python3.6/site-packages/flask_login/utils.py", line 272, in decorated_view
    return func(*args, **kwargs)
  File "/home/akshay/Documents/flask-projects/microblog/micro-venv/app/routes.py", line 23, in index
    return render_template('index.html',title='Home',form = form,posts = posts)
  File "/home/akshay/Documents/flask-projects/microblog/micro-venv/lib/python3.6/site-packages/flask/templating.py", line 140, in render_template
    ctx.app,
  File "/home/akshay/Documents/flask-projects/microblog/micro-venv/lib/python3.6/site-packages/flask/templating.py", line 120, in _render
    rv = template.render(context)
  File "/home/akshay/Documents/flask-projects/microblog/micro-venv/lib/python3.6/site-packages/jinja2/environment.py", line 1090, in render
    self.environment.handle_exception()
  File "/home/akshay/Documents/flask-projects/microblog/micro-venv/lib/python3.6/site-packages/jinja2/environment.py", line 832, in handle_exception
    reraise(*rewrite_traceback_stack(source=source))
  File "/home/akshay/Documents/flask-projects/microblog/micro-venv/lib/python3.6/site-packages/jinja2/_compat.py", line 28, in reraise
    raise value.with_traceback(tb)
  File "/home/akshay/Documents/flask-projects/microblog/micro-venv/app/templates/index.html", line 1, in top-level template code
    {% extends "base.html" %}
  File "/home/akshay/Documents/flask-projects/microblog/micro-venv/app/templates/base.html", line 36, in top-level template code
    {% block content %}{% endblock %}
  File "/home/akshay/Documents/flask-projects/microblog/micro-venv/app/templates/index.html", line 18, in block "content"
    {% for post in posts %}
TypeError: 'Pagination' object is not iterable
2020-12-19 19:34:12,483 INFO: Microblog startup [in /home/akshay/Documents/flask-projects/microblog/micro-venv/app/__init__.py:38]
2020-12-19 21:52:39,666 INFO: Microblog startup [in /home/akshay/Documents/flask-projects/microblog/micro-venv/app/__init__.py:38]
